<?xml version="1.0"?>
<!-- =================================================================================== -->
<!-- |    This document was autogenerated by xacro from mmrobot.urdf.xacro             | -->
<!-- |    EDITING THIS FILE BY HAND IS NOT RECOMMENDED                                 | -->
<!-- =================================================================================== -->
<robot name="albert">
  <link name="world"/>
  <link name="world_baske_link_x"/>
  <link name="world_baske_link_y"/>
  <joint name="world_base_x" type="prismatic">
    <origin rpy="0 0 0" xyz="0 0 0"/>
    <parent link="world"/>
    <child link="world_base_link_x"/>
    <axis xyz="1 0 0"/>
    <limit effort="100" lower="-15" upper="15" velocity="5"/>
  </joint>
  <joint name="world_base_y" type="prismatic">
    <origin rpy="0 0 0" xyz="0 0 0"/>
    <parent link="world_base_link_x"/>
    <child link="world_base_link_y"/>
    <axis xyz="0 1 0"/>
    <limit effort="100" lower="-15" upper="15" velocity="5"/>
  </joint>
  <joint name="world_base_theta" type="revolute">
    <origin rpy="0 0 0" xyz="0 0 0"/>
    <parent link="world_base_link_y"/>
    <child link="base_link"/>
    <axis xyz="0 0 1"/>
    <limit effort="100" lower="-15" upper="15" velocity="5"/>
  </joint>
  <link name="internal_link">
    <inertial>
      <origin rpy="0 0 0" xyz="0 0.19 -0.031"/>
      <mass value="31"/>
      <inertia ixx="1.19" ixy="0" ixz="0" iyy="1.82" iyz="0.0" izz="0.68"/>
    </inertial>
  </link>
  <joint name="internal_joint" type="fixed">
    <origin rpy="1.5708 0 0" xyz="0 0 0"/>
    <parent link="chassis_link"/>
    <child link="internal_link"/>
    <axis xyz="0 0 0"/>
  </joint>
  <link name="lift_link">
    <inertial>
      <origin rpy="0 0 0" xyz="0 0.076 0"/>
      <mass value="10"/>
      <inertia ixx="0.47" ixy="0" ixz="0" iyy="0.74" iyz="0" izz="0.29"/>
    </inertial>
  </link>
  <joint name="lift_joint" type="fixed">
    <origin rpy="1.5708 0 0" xyz="0 0 0.177"/>
    <parent link="chassis_link"/>
    <child link="lift_link"/>
    <axis xyz="0 1 0"/>
    <limit effort="10000.0" lower="0" upper="0.078" velocity="0.02"/>
    <dynamics damping="100.0" friction="100"/>
  </joint>
  <link name="top_mount_bottom">
    <inertial>
      <origin rpy="0 0 0" xyz="0 0 0"/>
      <mass value="10"/>
      <inertia ixx="0.50" ixy="0" ixz="0" iyy="0.50" iyz="0" izz="1.00"/>
    </inertial>
  </link>
  <joint name="top_mount_bottom_joint" type="fixed">
    <origin rpy="0 -1.5707 -1.5707" xyz="0 0.1125 0"/>
    <parent link="lift_link"/>
    <child link="top_mount_bottom"/>
  </joint>
  <link name="extrusion1">
    <inertial>
      <origin rpy="0 0 0" xyz="0 0 0"/>
      <mass value="1"/>
      <inertia ixx="0.50" ixy="0" ixz="0" iyy="0.50" iyz="0" izz="0.20"/>
    </inertial>
  </link>
  <joint name="extrusion1_joint" type="fixed">
    <origin rpy="0 0 0" xyz="-0.2785 0.1835 0"/>
    <parent link="top_mount_bottom"/>
    <child link="extrusion1"/>
  </joint>
  <link name="top_mount">
    <inertial>
      <origin rpy="0 0 0" xyz="0 0 0"/>
      <mass value="10"/>
      <inertia ixx="0.50" ixy="0" ixz="0" iyy="0.50" iyz="0" izz="1.00"/>
    </inertial>
  </link>
  <!-- 0.27 in z direction because extrusion is 0.30, and plate is 0.1 -->
  <joint name="top_mount_joint" type="fixed">
    <origin rpy="0 0 0" xyz="0.2785 -0.1835 0.31"/>
    <parent link="extrusion1"/>
    <child link="top_mount"/>
  </joint>
  <link name="base_link">
    <inertial>
      <origin rpy="0 0 0" xyz="0 0 0"/>
      <mass value="1"/>
      <inertia ixx="0.2" ixy="0" ixz="0" iyy="0.2" iyz="0" izz="0.2"/>
    </inertial>
  </link>
  <joint name="base_chassis_joint" type="fixed">
    <origin rpy="0 0 1.5708" xyz="0.15 0 0"/>
    <parent link="base_link"/>
    <child link="chassis_link"/>
  </joint>
  <joint name="mmrobot_joint_top_mount" type="fixed">
    <parent link="top_mount"/>
    <child link="mmrobot_link0"/>
    <origin rpy="0 0 0" xyz="-0.15 0 0"/>
  </joint>
  <!-- end for simulation -->
  <link name="mmrobot_link0">
    <inertial>
      <origin rpy="0 0 0" xyz="0 0 0"/>
      <mass value="3.06"/>
      <inertia ixx="0.3" ixy="0.0" ixz="0.0" iyy="0.3" iyz="0.0" izz="0.3"/>
    </inertial>
    <!-- end for simulation -->
  </link>
  <link name="mmrobot_link1">
    <inertial>
      <origin rpy="0 0 0" xyz="0 0 0"/>
      <mass value="2.34"/>
      <inertia ixx="0.3" ixy="0.0" ixz="0.0" iyy="0.3" iyz="0.0" izz="0.3"/>
    </inertial>
    <!-- end for simulation -->
  </link>
  <joint name="mmrobot_joint1" type="revolute">
    <safety_controller k_position="100.0" k_velocity="40.0" soft_lower_limit="-2.8973" soft_upper_limit="2.8973"/>
    <origin rpy="0 0 0" xyz="0 0 0.333"/>
    <parent link="mmrobot_link0"/>
    <child link="mmrobot_link1"/>
    <axis xyz="0 0 1"/>
    <limit effort="87" lower="-2.8973" upper="2.8973" velocity="2.1750"/>
    <!-- for simulation -->
    <dynamics damping="1.0"/>
    <!-- end for simulation -->
  </joint>
  <link name="mmrobot_link2">
    <!-- for simulation -->
    <inertial>
      <origin rpy="0 0 0" xyz="0 0 0"/>
      <mass value="2.36"/>
      <inertia ixx="0.3" ixy="0.0" ixz="0.0" iyy="0.3" iyz="0.0" izz="0.3"/>
    </inertial>
    <!-- end for simulation -->
  </link>
  <joint name="mmrobot_joint2" type="revolute">
    <safety_controller k_position="100.0" k_velocity="40.0" soft_lower_limit="-1.7628" soft_upper_limit="1.7628"/>
    <origin rpy="-1.57079632679 0 0" xyz="0 0 0"/>
    <parent link="mmrobot_link1"/>
    <child link="mmrobot_link2"/>
    <axis xyz="0 0 1"/>
    <limit effort="87" lower="-1.7628" upper="1.7628" velocity="2.1750"/>
    <!-- for simulation -->
    <dynamics damping="1.0"/>
    <!-- end for simulation -->
  </joint>
  <link name="mmrobot_link3">
    <inertial>
      <origin rpy="0 0 0" xyz="0 0 0"/>
      <mass value="2.38"/>
      <inertia ixx="0.3" ixy="0.0" ixz="0.0" iyy="0.3" iyz="0.0" izz="0.3"/>
    </inertial>
    <!-- end for simulation -->
  </link>
  <joint name="mmrobot_joint3" type="revolute">
    <safety_controller k_position="100.0" k_velocity="40.0" soft_lower_limit="-2.8973" soft_upper_limit="2.8973"/>
    <origin rpy="1.57079632679 0 0" xyz="0 -0.316 0"/>
    <parent link="mmrobot_link2"/>
    <child link="mmrobot_link3"/>
    <axis xyz="0 0 1"/>
    <limit effort="87" lower="-2.8973" upper="2.8973" velocity="2.1750"/>
    <!-- for simulation -->
    <dynamics damping="1.0"/>
    <!-- end for simulation -->
  </joint>
  <link name="mmrobot_link4">
    <inertial>
      <origin rpy="0 0 0" xyz="0 0 0"/>
      <mass value="2.43"/>
      <inertia ixx="0.3" ixy="0.0" ixz="0.0" iyy="0.3" iyz="0.0" izz="0.3"/>
    </inertial>
    <!-- end for simulation -->
  </link>
  <joint name="mmrobot_joint4" type="revolute">
    <safety_controller k_position="100.0" k_velocity="40.0" soft_lower_limit="-1.50100" soft_upper_limit="1.500996"/>
    <!-- changed joint init position to be closer to home position-->
    <origin rpy="1.57079632679 1.57079632679 0" xyz="0.0825 0 0"/>
    <parent link="mmrobot_link3"/>
    <child link="mmrobot_link4"/>
    <axis xyz="0 0 1"/>
    <limit effort="87" lower="-1.50100" upper="1.500996" velocity="2.1750"/>
    <!-- for simulation -->
    <dynamics damping="1.0"/>
    <!-- end for simulation -->
  </joint>
  <link name="mmrobot_link5">
    <inertial>
      <origin rpy="0 0 0" xyz="0 0 0"/>
      <mass value="3.5"/>
      <inertia ixx="0.3" ixy="0.0" ixz="0.0" iyy="0.3" iyz="0.0" izz="0.3"/>
    </inertial>
    <!-- end for simulation -->
  </link>
  <joint name="mmrobot_joint5" type="revolute">
    <safety_controller k_position="100.0" k_velocity="40.0" soft_lower_limit="-2.8973" soft_upper_limit="2.8973"/>
    <origin rpy="-1.57079632679 0 0" xyz="-0.0825 0.384 0"/>
    <parent link="mmrobot_link4"/>
    <child link="mmrobot_link5"/>
    <axis xyz="0 0 1"/>
    <limit effort="12" lower="-2.8973" upper="2.8973" velocity="2.6100"/>
    <!-- for simulation -->
    <dynamics damping="1.0"/>
    <!-- end for simulation -->
  </joint>
  <link name="mmrobot_link6">
    <inertial>
      <origin rpy="0 0 0" xyz="0 0 0"/>
      <mass value="1.47"/>
      <inertia ixx="0.3" ixy="0.0" ixz="0.0" iyy="0.3" iyz="0.0" izz="0.3"/>
    </inertial>
    <!-- end for simulation -->
  </link>
  <joint name="mmrobot_joint6" type="revolute">
    <safety_controller k_position="100.0" k_velocity="40.0" soft_lower_limit="-1.58830" soft_upper_limit="2.1817"/>
    <!-- changed values to be out of collision at start of simulation-->
    <origin rpy="1.57079632679 -1.57079632679 0" xyz="0 0 0"/>
    <parent link="mmrobot_link5"/>
    <child link="mmrobot_link6"/>
    <axis xyz="0 0 1"/>
    <limit effort="12" lower="-1.58830" upper="2.1817" velocity="2.6100"/>
    <!-- for simulation -->
    <dynamics damping="1.0"/>
    <!-- end for simulation -->
  </joint>
  <link name="mmrobot_link7">
    <inertial>
      <origin rpy="0 0 0" xyz="0 0 0"/>
      <mass value="0.45"/>
      <inertia ixx="0.3" ixy="0.0" ixz="0.0" iyy="0.3" iyz="0.0" izz="0.3"/>
    </inertial>
    <!-- end for simulation -->
  </link>
  <joint name="mmrobot_joint7" type="revolute">
    <safety_controller k_position="100.0" k_velocity="40.0" soft_lower_limit="-2.8973" soft_upper_limit="2.8973"/>
    <origin rpy="1.57079632679 0 0" xyz="0.088 0 0"/>
    <parent link="mmrobot_link6"/>
    <child link="mmrobot_link7"/>
    <axis xyz="0 0 1"/>
    <limit effort="12" lower="-2.8973" upper="2.8973" velocity="2.6100"/>
    <!-- for simulation -->
    <dynamics damping="1.0"/>
    <!-- end for simulation -->
  </joint>
  <link name="mmrobot_link8">
    <!-- for simulation -->
    <inertial>
      <origin rpy="0 0 0" xyz="0 0 0"/>
      <mass value="0.0"/>
      <inertia ixx="0.3" ixy="0.0" ixz="0.0" iyy="0.3" iyz="0.0" izz="0.3"/>
    </inertial>
    <!-- end for simulation -->
  </link>
  <joint name="mmrobot_joint8" type="fixed">
    <origin rpy="0 0 0" xyz="0 0 0.107"/>
    <parent link="mmrobot_link7"/>
    <child link="mmrobot_link8"/>
    <axis xyz="0 0 0"/>
  </joint>
  <link name="mmrobot_link9"/>
    <inertial>
      <mass value="0.01"/>
      <origin rpy="0 0 0" xyz="0.0 0.0 0.0"/>
      <inertia ixx="0.000888868887021" ixy="-0.00012239074652" ixz="3.98699829666e-05" iyy="0.000888001373233" iyz="-9.33825115206e-05" izz="0.0007176834609"/>
    </inertial>
  <joint name="mmrobot_joint9" type="fixed">
    <origin rpy="0 0 0" xyz="0 0 0.020"/>
    <parent link="mmrobot_link8"/>
    <child link="mmrobot_link9"/>
    <axis xyz="0 0 0"/>
  </joint>
  <joint name="mmrobot_hand_joint" type="fixed">
    <parent link="mmrobot_link8"/>
    <child link="mmrobot_hand"/>
    <origin rpy="0 0 -0.785398163397" xyz="0 0 0"/>
  </joint>
  <link name="mmrobot_hand">
    <inertial>
      <origin rpy="0 0 0" xyz="0 0 0"/>
      <mass value="0.68"/>
      <inertia ixx="0.1" ixy="0.0" ixz="0.0" iyy="0.1" iyz="0.0" izz="0.1"/>
    </inertial>
    <!-- end for simulation -->
  </link>
  <link name="mmrobot_leftfinger">
    <inertial>
      <origin rpy="0 0 0" xyz="0 0 0"/>
      <mass value="0.01"/>
      <inertia ixx="0.1" ixy="0.0" ixz="0.0" iyy="0.1" iyz="0.0" izz="0.1"/>
    </inertial>
    <!-- end for simulation -->
  </link>
  <link name="mmrobot_rightfinger">
    <inertial>
      <origin rpy="0 0 0" xyz="0 0 0"/>
      <mass value="0.01"/>
      <inertia ixx="0.1" ixy="0.0" ixz="0.0" iyy="0.1" iyz="0.0" izz="0.1"/>
    </inertial>
    <!-- end for simulation -->
  </link>
  <joint name="mmrobot_finger_joint1" type="prismatic">
    <parent link="mmrobot_hand"/>
    <child link="mmrobot_leftfinger"/>
    <origin rpy="0 0 0" xyz="0 0 0.0584"/>
    <axis xyz="0 1 0"/>
    <limit effort="20" lower="0.0" upper="0.04" velocity="0.2"/>
  </joint>
  <joint name="mmrobot_finger_joint2" type="prismatic">
    <parent link="mmrobot_hand"/>
    <child link="mmrobot_rightfinger"/>
    <origin rpy="0 0 0" xyz="0 0 0.0584"/>
    <axis xyz="0 -1 0"/>
    <limit effort="20" lower="0.0" upper="0.04" velocity="0.2"/>
  </joint>
  <!-- Link0 -->
</robot>

