<?xml version="1.0"?>
<!-- =================================================================================== -->
<!-- |    This document was autogenerated by xacro from mmrobot.urdf.xacro             | -->
<!-- |    EDITING THIS FILE BY HAND IS NOT RECOMMENDED                                 | -->
<!-- =================================================================================== -->
<robot name="albert">
  <link name="world"/>
  <link name="world_base_link_x"/>
  <link name="world_base_link_y"/>
  <joint name="world_base_x" type="prismatic">
    <origin rpy="0 0 0" xyz="0 0 0"/>
    <parent link="world"/>
    <child link="world_base_link_x"/>
    <axis xyz="1 0 0"/>
    <limit effort="100" lower="-15" upper="15" velocity="5"/>
  </joint>
  <joint name="world_base_y" type="prismatic">
    <origin rpy="0 0 0" xyz="0 0 0"/>
    <parent link="world_base_link_x"/>
    <child link="world_base_link_y"/>
    <axis xyz="0 1 0"/>
    <limit effort="100" lower="-15" upper="15" velocity="5"/>
  </joint>
  <joint name="world_base_theta" type="revolute">
    <origin rpy="0 0 0" xyz="0 0 0"/>
    <parent link="world_base_link_y"/>
    <child link="base_link"/>
    <axis xyz="0 0 1"/>
    <limit effort="100" lower="-15" upper="15" velocity="5"/>
  </joint>
  <link name="base_link">
    <inertial>
      <origin rpy="0 0 0" xyz="0 0 0"/>
      <mass value="1"/>
      <inertia ixx="0.2" ixy="0" ixz="0" iyy="0.2" iyz="0" izz="0.2"/>
    </inertial>
  </link>
  <link name="chassis_link"/>
  <joint name="base_chassis_joint" type="fixed">
    <origin rpy="0 0 -1.5708" xyz="0.0 0 0"/>
    <parent link="base_link"/>
    <child link="chassis_link"/>
  </joint>
  <link name="ee_link"/>
  <joint name="ee_joint" type="fixed">
    <origin rpy="0 0 0" xyz="0.4 0 0"/>
    <parent link="chassis_link"/>
    <child link="ee_link"/>
  </joint>
</robot>

